<?xml version="1.0" encoding="utf-8"?>
<!-- This URDF was automatically created by SolidWorks to URDF Exporter! Originally created by Stephen Brawner (brawner@gmail.com) 
     Commit Version: 1.6.0-4-g7f85cfe  Build Version: 1.6.7995.38578
     For more information, please see http://wiki.ros.org/sw_urdf_exporter -->
<robot
  name="Snake_Assembly">
  <link
    name="Head">
    <inertial>
      <origin
        xyz="-0.0773298413692836 -0.000367823958700774 0.0256915918630202"
        rpy="0 0 0" />
      <mass
        value="0.126882468775081" />
      <inertia
        ixx="8.92133825913495E-05"
        ixy="8.70853305270439E-09"
        ixz="-1.65508843724945E-06"
        iyy="0.000160285197403636"
        iyz="5.11782398679065E-10"
        izz="0.000215528990386258" />
    </inertial>
    <visual>
      <origin
        xyz="0 0 0"
        rpy="0 0 0" />
      <geometry>
        <mesh
          filename="package://Snake_Assembly/meshes/Head.STL" />
      </geometry>
      <material
        name="">
        <color
          rgba="0.752941176470588 0.752941176470588 0.752941176470588 1" />
      </material>
    </visual>
    <collision>
      <origin
        xyz="0 0 0"
        rpy="0 0 0" />
      <geometry>
        <mesh
          filename="package://Snake_Assembly/meshes/Head.STL" />
      </geometry>
    </collision>
  </link>
  <link
    name="Motor 1">
    <inertial>
      <origin
        xyz="-0.0120001503975481 0.000121970944779873 0.000495878530213562"
        rpy="0 0 0" />
      <mass
        value="0.0569176277607128" />
      <inertia
        ixx="1.02302735970703E-05"
        ixy="-5.82120294433897E-10"
        ixz="7.69441167803847E-10"
        iyy="1.43924882902026E-05"
        iyz="3.44003507752819E-07"
        izz="1.43925048825667E-05" />
    </inertial>
    <visual>
      <origin
        xyz="0 0 0"
        rpy="0 0 0" />
      <geometry>
        <mesh
          filename="package://Snake_Assembly/meshes/Motor 1.STL" />
      </geometry>
      <material
        name="">
        <color
          rgba="0.792156862745098 0.819607843137255 0.933333333333333 1" />
      </material>
    </visual>
    <collision>
      <origin
        xyz="0 0 0"
        rpy="0 0 0" />
      <geometry>
        <mesh
          filename="package://Snake_Assembly/meshes/Motor 1.STL" />
      </geometry>
    </collision>
  </link>
  <joint
    name="Motor 1 Pitch"
    type="revolute">
    <origin
      xyz="-0.14899 0 0.027"
      rpy="0 0 0" />
    <parent
      link="Head" />
    <child
      link="Motor 1" />
    <axis
      xyz="0 0 1" />
    <limit
      lower="-0.6"
      upper="0.6"
      effort="0.8"
      velocity="1.2" />
  </joint>
  <link
    name="Connector 1">
    <inertial>
      <origin
        xyz="-0.0315 1.12648605721244E-16 1.52448022955332E-10"
        rpy="0 0 0" />
      <mass
        value="0.0430527075111026" />
      <inertia
        ixx="2.57478329077417E-05"
        ixy="2.19719850209398E-20"
        ixz="-3.72371181524516E-21"
        iyy="2.97255523427383E-05"
        iyz="1.76027720796545E-20"
        izz="2.97255523427383E-05" />
    </inertial>
    <visual>
      <origin
        xyz="0 0 0"
        rpy="0 0 0" />
      <geometry>
        <mesh
          filename="package://Snake_Assembly/meshes/Connector 1.STL" />
      </geometry>
      <material
        name="">
        <color
          rgba="0.792156862745098 0.819607843137255 0.933333333333333 1" />
      </material>
    </visual>
    <collision>
      <origin
        xyz="0 0 0"
        rpy="0 0 0" />
      <geometry>
        <mesh
          filename="package://Snake_Assembly/meshes/Connector 1.STL" />
      </geometry>
    </collision>
  </link>
  <joint
    name="Motor 1 Yaw"
    type="revolute">
    <origin
      xyz="-0.024 -0.000374 0"
      rpy="0 0 0" />
    <parent
      link="Motor 1" />
    <child
      link="Connector 1" />
    <axis
      xyz="0 1 0" />
    <limit
      lower="-0.6"
      upper="0.6"
      effort="0.8"
      velocity="1.2" />
  </joint>
  <link
    name="Motor 2">
    <inertial>
      <origin
        xyz="-0.0119998503185918 0.000495878377765638 0.000495971402698948"
        rpy="0 0 0" />
      <mass
        value="0.0569176277607127" />
      <inertia
        ixx="1.02302735970702E-05"
        ixy="-7.69441167800332E-10"
        ixz="5.8212029442761E-10"
        iyy="1.43925048825667E-05"
        iyz="3.44003507752817E-07"
        izz="1.43924882902026E-05" />
    </inertial>
    <visual>
      <origin
        xyz="0 0 0"
        rpy="0 0 0" />
      <geometry>
        <mesh
          filename="package://Snake_Assembly/meshes/Motor 2.STL" />
      </geometry>
      <material
        name="">
        <color
          rgba="0.792156862745098 0.819607843137255 0.933333333333333 1" />
      </material>
    </visual>
    <collision>
      <origin
        xyz="0 0 0"
        rpy="0 0 0" />
      <geometry>
        <mesh
          filename="package://Snake_Assembly/meshes/Motor 2.STL" />
      </geometry>
    </collision>
  </link>
  <joint
    name="Motor 2 Pitch"
    type="revolute">
    <origin
      xyz="-0.063 0 0"
      rpy="0 0 0" />
    <parent
      link="Connector 1" />
    <child
      link="Motor 2" />
    <axis
      xyz="0 0 1" />
    <limit
      lower="-0.6"
      upper="0.6"
      effort="0.8"
      velocity="1.2" />
  </joint>
  <link
    name="Connector 2">
    <inertial>
      <origin
        xyz="-0.0314999999999999 -2.8122035949929E-15 1.52448425411178E-10"
        rpy="0 0 0" />
      <mass
        value="0.0430527075111026" />
      <inertia
        ixx="2.57478329077417E-05"
        ixy="2.68833699079734E-20"
        ixz="4.88219950864592E-21"
        iyy="2.97255523427383E-05"
        iyz="1.51480398199948E-20"
        izz="2.97255523427383E-05" />
    </inertial>
    <visual>
      <origin
        xyz="0 0 0"
        rpy="0 0 0" />
      <geometry>
        <mesh
          filename="package://Snake_Assembly/meshes/Connector 2.STL" />
      </geometry>
      <material
        name="">
        <color
          rgba="0.792156862745098 0.819607843137255 0.933333333333333 1" />
      </material>
    </visual>
    <collision>
      <origin
        xyz="0 0 0"
        rpy="0 0 0" />
      <geometry>
        <mesh
          filename="package://Snake_Assembly/meshes/Connector 2.STL" />
      </geometry>
    </collision>
  </link>
  <joint
    name="Motor 2 Yaw"
    type="revolute">
    <origin
      xyz="-0.024 0 0"
      rpy="0 0 0" />
    <parent
      link="Motor 2" />
    <child
      link="Connector 2" />
    <axis
      xyz="0 1 0" />
    <limit
      lower="-0.6"
      upper="0.6"
      effort="0.8"
      velocity="1.2" />
  </joint>
  <link
    name="Motor 3">
    <inertial>
      <origin
        xyz="-0.0119998503185919 0.000495878377762661 0.000495971402698948"
        rpy="0 0 0" />
      <mass
        value="0.0569176277607127" />
      <inertia
        ixx="1.02302735970703E-05"
        ixy="-7.69441167797286E-10"
        ixz="5.82120294423903E-10"
        iyy="1.43925048825667E-05"
        iyz="3.44003507752819E-07"
        izz="1.43924882902026E-05" />
    </inertial>
    <visual>
      <origin
        xyz="0 0 0"
        rpy="0 0 0" />
      <geometry>
        <mesh
          filename="package://Snake_Assembly/meshes/Motor 3.STL" />
      </geometry>
      <material
        name="">
        <color
          rgba="0.792156862745098 0.819607843137255 0.933333333333333 1" />
      </material>
    </visual>
    <collision>
      <origin
        xyz="0 0 0"
        rpy="0 0 0" />
      <geometry>
        <mesh
          filename="package://Snake_Assembly/meshes/Motor 3.STL" />
      </geometry>
    </collision>
  </link>
  <joint
    name="Motor 3 Pitch"
    type="revolute">
    <origin
      xyz="-0.063 0 0"
      rpy="0 0 0" />
    <parent
      link="Connector 2" />
    <child
      link="Motor 3" />
    <axis
      xyz="0 0 1" />
    <limit
      lower="-0.6"
      upper="0.6"
      effort="0.8"
      velocity="1.2" />
  </joint>
  <link
    name="Connector 3">
    <inertial>
      <origin
        xyz="-0.0314999999999999 -1.8436857943116E-15 1.5244901521716E-10"
        rpy="0 0 0" />
      <mass
        value="0.0430527075111026" />
      <inertia
        ixx="2.57478329077417E-05"
        ixy="2.51385358033693E-20"
        ixz="-2.48154183765911E-21"
        iyy="2.97255523427383E-05"
        iyz="1.66987086159143E-20"
        izz="2.97255523427383E-05" />
    </inertial>
    <visual>
      <origin
        xyz="0 0 0"
        rpy="0 0 0" />
      <geometry>
        <mesh
          filename="package://Snake_Assembly/meshes/Connector 3.STL" />
      </geometry>
      <material
        name="">
        <color
          rgba="0.792156862745098 0.819607843137255 0.933333333333333 1" />
      </material>
    </visual>
    <collision>
      <origin
        xyz="0 0 0"
        rpy="0 0 0" />
      <geometry>
        <mesh
          filename="package://Snake_Assembly/meshes/Connector 3.STL" />
      </geometry>
    </collision>
  </link>
  <joint
    name="Motor 3 Yaw"
    type="revolute">
    <origin
      xyz="-0.024 0 0"
      rpy="0 0 0" />
    <parent
      link="Motor 3" />
    <child
      link="Connector 3" />
    <axis
      xyz="0 1 0" />
    <limit
      lower="-0.6"
      upper="0.6"
      effort="0.8"
      velocity="1.2" />
  </joint>
  <link
    name="Motor 4">
    <inertial>
      <origin
        xyz="-0.0120001503975481 0.000495971250249118 0.000495878530213534"
        rpy="0 0 0" />
      <mass
        value="0.0569176277607128" />
      <inertia
        ixx="1.02302735970703E-05"
        ixy="-5.82120294431644E-10"
        ixz="7.69441167798525E-10"
        iyy="1.43924882902027E-05"
        iyz="3.4400350775282E-07"
        izz="1.43925048825667E-05" />
    </inertial>
    <visual>
      <origin
        xyz="0 0 0"
        rpy="0 0 0" />
      <geometry>
        <mesh
          filename="package://Snake_Assembly/meshes/Motor 4.STL" />
      </geometry>
      <material
        name="">
        <color
          rgba="0.792156862745098 0.819607843137255 0.933333333333333 1" />
      </material>
    </visual>
    <collision>
      <origin
        xyz="0 0 0"
        rpy="0 0 0" />
      <geometry>
        <mesh
          filename="package://Snake_Assembly/meshes/Motor 4.STL" />
      </geometry>
    </collision>
  </link>
  <joint
    name="Motor 4 Pitch"
    type="revolute">
    <origin
      xyz="-0.063 0 0"
      rpy="0 0 0" />
    <parent
      link="Connector 3" />
    <child
      link="Motor 4" />
    <axis
      xyz="0 0 1" />
    <limit
      lower="-0.6"
      upper="0.6"
      effort="0.8"
      velocity="1.2" />
  </joint>
  <link
    name="Connector 4">
    <inertial>
      <origin
        xyz="-0.0315 -1.86406879515433E-15 1.52447873769113E-10"
        rpy="0 0 0" />
      <mass
        value="0.0430527075111026" />
      <inertia
        ixx="2.57478329077417E-05"
        ixy="2.05502683431143E-20"
        ixz="-1.74483410460399E-21"
        iyy="2.97255523427383E-05"
        iyz="1.82238228703089E-20"
        izz="2.97255523427383E-05" />
    </inertial>
    <visual>
      <origin
        xyz="0 0 0"
        rpy="0 0 0" />
      <geometry>
        <mesh
          filename="package://Snake_Assembly/meshes/Connector 4.STL" />
      </geometry>
      <material
        name="">
        <color
          rgba="0.792156862745098 0.819607843137255 0.933333333333333 1" />
      </material>
    </visual>
    <collision>
      <origin
        xyz="0 0 0"
        rpy="0 0 0" />
      <geometry>
        <mesh
          filename="package://Snake_Assembly/meshes/Connector 4.STL" />
      </geometry>
    </collision>
  </link>
  <joint
    name="Motor 4 Yaw"
    type="revolute">
    <origin
      xyz="-0.02400000071614 0 0"
      rpy="0 0 0" />
    <parent
      link="Motor 4" />
    <child
      link="Connector 4" />
    <axis
      xyz="0 1 0" />
    <limit
      lower="-0.6"
      upper="0.6"
      effort="0.8"
      velocity="1.2" />
  </joint>
  <link
    name="Motor 5">
    <inertial>
      <origin
        xyz="-0.0119998503185921 0.000495878377763779 0.000495971402698976"
        rpy="0 0 0" />
      <mass
        value="0.0569176277607127" />
      <inertia
        ixx="1.02302735970702E-05"
        ixy="-7.69441167797774E-10"
        ixz="5.82120294428564E-10"
        iyy="1.43925048825667E-05"
        iyz="3.44003507752819E-07"
        izz="1.43924882902026E-05" />
    </inertial>
    <visual>
      <origin
        xyz="0 0 0"
        rpy="0 0 0" />
      <geometry>
        <mesh
          filename="package://Snake_Assembly/meshes/Motor 5.STL" />
      </geometry>
      <material
        name="">
        <color
          rgba="0.792156862745098 0.819607843137255 0.933333333333333 1" />
      </material>
    </visual>
    <collision>
      <origin
        xyz="0 0 0"
        rpy="0 0 0" />
      <geometry>
        <mesh
          filename="package://Snake_Assembly/meshes/Motor 5.STL" />
      </geometry>
    </collision>
  </link>
  <joint
    name="Motor 5 Pitch"
    type="revolute">
    <origin
      xyz="-0.063 0 0"
      rpy="0 0 0" />
    <parent
      link="Connector 4" />
    <child
      link="Motor 5" />
    <axis
      xyz="0 0 1" />
    <limit
      lower="-0.6"
      upper="0.6"
      effort="0.8"
      velocity="1.2" />
  </joint>
  <link
    name="Tail">
    <inertial>
      <origin
        xyz="-0.0513936639534015 1.12044782427198E-07 0.001179015401235"
        rpy="0 0 0" />
      <mass
        value="0.0573755283614792" />
      <inertia
        ixx="3.42744348747828E-05"
        ixy="1.26390885653235E-09"
        ixz="1.07017727829772E-08"
        iyy="5.50507811947081E-05"
        iyz="4.76711059275756E-09"
        izz="5.33986092158264E-05" />
    </inertial>
    <visual>
      <origin
        xyz="0 0 0"
        rpy="0 0 0" />
      <geometry>
        <mesh
          filename="package://Snake_Assembly/meshes/Tail.STL" />
      </geometry>
      <material
        name="">
        <color
          rgba="0.752941176470588 0.752941176470588 0.752941176470588 1" />
      </material>
    </visual>
    <collision>
      <origin
        xyz="0 0 0"
        rpy="0 0 0" />
      <geometry>
        <mesh
          filename="package://Snake_Assembly/meshes/Tail.STL" />
      </geometry>
    </collision>
  </link>
  <joint
    name="Motor 5 Yaw"
    type="revolute">
    <origin
      xyz="-0.024 0 0"
      rpy="0 0 0" />
    <parent
      link="Motor 5" />
    <child
      link="Tail" />
    <axis
      xyz="0 1 0" />
    <limit
      lower="-0.6"
      upper="0.6"
      effort="0.8"
      velocity="1.2" />
  </joint>
</robot>
